Workbook

Sheet Tổng quan 26 tuần
A1: LỘ TRÌNH AI-DRIVEN SDLC 6 THÁNG (26 TUẦN)
A2: Bản đề xuất 30/10/2026 · GĐ1 7 tuần + GĐ2 12 tuần + GĐ3 Capstone & OJT 7 tuần
A4: Tuần | B4: Giai đoạn | C4: Module / Sprint | D4: Chủ đề | E4: Thi | F4: Gộp từ lộ trình cũ
A5: 1 | B5: GĐ1 · Fullstack nền tảng | D5: Git + HTML/CSS Responsive | F5: GĐ1 cũ T1 + T2
A6: 2 | B6: GĐ1 · Fullstack nền tảng | D6: JavaScript ES6+ & Async/Fetch API | F6: GĐ1 cũ T3 + T4 (bỏ phần fetch bị lặp)
A7: 3 | B7: GĐ1 · Fullstack nền tảng | D7: React: Component, Props, State, Hooks | F7: GĐ1 cũ T5 + useEffect của T6
A8: 4 | B8: GĐ1 · Fullstack nền tảng | D8: React: Forms, Context, Routing | F8: GĐ1 cũ T6
A9: 5 | B9: GĐ1 · Fullstack nền tảng | D9: Node.js + Express REST API | F9: GĐ1 cũ T7
A10: 6 | B10: GĐ1 · Fullstack nền tảng | D10: Database với Sequelize | F10: GĐ1 cũ T8 (Auth chuyển sang GĐ2 tuần 14)
A11: 7 | B11: GĐ1 · Fullstack nền tảng | D11: Tích hợp + Thi cuối Giai đoạn 1 | E11: Thi | F11: GĐ1 cũ T10
A12: 8 | B12: GĐ2 · AI-Driven SDLC | C12: M1 · AI-assisted Programming | D12: AI SDLC toàn cảnh + Workspace & Memory | F12: GĐ2 cũ T1 + T2
A13: 9 | B13: GĐ2 · AI-Driven SDLC | C13: M1 · AI-assisted Programming | D13: AGENTS.md, Governance, MCP + Thi Phase I | E13: Thi | F13: GĐ2 cũ T3
A14: 10 | B14: GĐ2 · AI-Driven SDLC | C14: M2 · Spec-first SE | D14: Requirement, MoSCoW + User Story & AC | F14: GĐ2 cũ T4 + T5
A15: 11 | B15: GĐ2 · AI-Driven SDLC | C15: M2 · Spec-first SE | D15: Wireframe + Database Contract & ERD | F15: GĐ2 cũ T5 + T6
A16: 12 | B16: GĐ2 · AI-Driven SDLC | C16: M2 · Spec-first SE | D16: API contract, Traceability, Plan, ADR + Thi Phase II | E16: Thi | F16: GĐ2 cũ T7 (thêm ADR)
A17: 13 | B17: GĐ2 · AI-Driven SDLC | C17: M3 · Agentic Fullstack | D17: TDD + Git workflow + Task contract | F17: GĐ2 cũ T8 + T9
A18: 14 | B18: GĐ2 · AI-Driven SDLC | C18: M3 · Agentic Fullstack | D18: Backend qua agent + DB + Auth | F18: GĐ2 cũ T9 + T10, GĐ1 cũ T9
A19: 15 | B19: GĐ2 · AI-Driven SDLC | C19: M3 · Agentic Fullstack | D19: Frontend + Tích hợp fullstack + E2E | F19: GĐ2 cũ T11 + T12
A20: 16 | B20: GĐ2 · AI-Driven SDLC | C20: M3 · Agentic Fullstack | D20: Diff review, Refactor + Thi Phase III | E20: Thi | F20: GĐ2 cũ T13
A21: 17 | B21: GĐ2 · AI-Driven SDLC | C21: M4 · Security, DevOps, Cloud | D21: Debug, Self-healing + Security & Legal/IP | F21: GĐ2 cũ T14 + T15
A22: 18 | B22: GĐ2 · AI-Driven SDLC | C22: M4 · Security, DevOps, Cloud | D22: Docker, CI, AI review gate + Deploy cloud | F22: GĐ2 cũ T16 + T17
A23: 19 | B23: GĐ2 · AI-Driven SDLC | C23: M4 · Security, DevOps, Cloud | D23: Observability, Maintenance + Thi Phase IV | E23: Thi | F23: GĐ2 cũ T17 + T18 (bỏ tuần thi riêng)
A24: 20 | B24: GĐ3 · Capstone & OJT (IOC) | C24: Kickoff · Gate M0–M1 | D24: Proposal, scope, AI usage policy, team agreement | F24: M5 cũ T19
A25: 21 | B25: GĐ3 · Capstone & OJT (IOC) | C25: Sprint 1 · Backend · Gate M2 | D25: Triển khai backend + integration test qua agent | F25: M5 cũ T20
A26: 22 | B26: GĐ3 · Capstone & OJT (IOC) | C26: Sprint 2 · Frontend · Gate M3 | D26: Frontend + fullstack flow + E2E | F26: M5 cũ T21
A27: 23 | B27: GĐ3 · Capstone & OJT (IOC) | C27: Sprint 3 · Hardening · Gate M4–M6 | D27: Diff review/refactor, security, Docker/CI, deploy release v1.0 | F27: M5 cũ T22
A28: 24 | B28: GĐ3 · Capstone & OJT (IOC) | C28: Brownfield 1 | D28: Nhận codebase của nhóm khác | F28: OJT cũ
A29: 25 | B29: GĐ3 · Capstone & OJT (IOC) | C29: Brownfield 2 | D29: Thực hiện change request + sửa bug | F29: OJT cũ
A30: 26 | B30: GĐ3 · Capstone & OJT (IOC) | C30: Defense · Gate M7 | D30: README tiếng Anh, demo, slide | E30: Thi | F30: M5 cũ T23 + OJT cũ

Sheet Thống kê thời lượng
A1: THỐNG KÊ THỜI LƯỢNG
A2: Ô vàng là giả định, có thể chỉnh; các ô còn lại tự tính theo công thức
A4: GIẢ ĐỊNH
A5: Giờ mỗi buổi GĐ2 | B5: 3 | C5: File chương trình chưa ghi thời lượng GĐ2; lấy 3 giờ/buổi như GĐ1
A6: Số buổi mỗi tuần GĐ2 | B6: 3 | C6: Tự học, Mentor, Giảng viên
A7: Số buổi có Mentor/GV mỗi tuần GĐ2 | B7: 2 | C7: Buổi 2 và Buổi 3
A8: Giờ có mentor mỗi tuần GĐ3 | B8: 9 | C8: Giả định: 3 buổi gate/review x 3 giờ; chỉnh theo kế hoạch IOC
A10: GĐ1: THỜI LƯỢNG THEO TUẦN
A11: Tuần | B11: Chủ đề | C11: Tự học trước (phút) | D11: Buổi 1 (phút) | E11: Buổi 2 (phút) | F11: Trên lớp (giờ) | G11: Tổng gồm tự học (giờ)
A12: 1 | B12: Git + HTML/CSS Responsive | C12: =SUMIFS('GĐ1 - Fullstack (7 tuần)'!$E$5:$E$95,'GĐ1 - Fullstack (7 tuần)'!$A$5:$A$95,A12,'GĐ1 - Fullstack (7 tuần)'!$C$5:$C$95,"Pre-class") -> 45 | D12: =SUMIFS('GĐ1 - Fullstack (7 tuần)'!$E$5:$E$95,'GĐ1 - Fullstack (7 tuần)'!$A$5:$A$95,A12,'GĐ1 - Fullstack (7 tuần)'!$C$5:$C$95,"Buổi 1") -> 180 | E12: =SUMIFS('GĐ1 - Fullstack (7 tuần)'!$E$5:$E$95,'GĐ1 - Fullstack (7 tuần)'!$A$5:$A$95,A12,'GĐ1 - Fullstack (7 tuần)'!$C$5:$C$95,"Buổi 2*") -> 180 | F12: =(D12+E12)/60 -> 6 | G12: =(C12+D12+E12)/60 -> 6.75
A13: 2 | B13: JavaScript ES6+ & Async/Fetch API | C13: =SUMIFS('GĐ1 - Fullstack (7 tuần)'!$E$5:$E$95,'GĐ1 - Fullstack (7 tuần)'!$A$5:$A$95,A13,'GĐ1 - Fullstack (7 tuần)'!$C$5:$C$95,"Pre-class") -> 45 | D13: =SUMIFS('GĐ1 - Fullstack (7 tuần)'!$E$5:$E$95,'GĐ1 - Fullstack (7 tuần)'!$A$5:$A$95,A13,'GĐ1 - Fullstack (7 tuần)'!$C$5:$C$95,"Buổi 1") -> 180 | E13: =SUMIFS('GĐ1 - Fullstack (7 tuần)'!$E$5:$E$95,'GĐ1 - Fullstack (7 tuần)'!$A$5:$A$95,A13,'GĐ1 - Fullstack (7 tuần)'!$C$5:$C$95,"Buổi 2*") -> 180 | F13: =(D13+E13)/60 -> 6 | G13: =(C13+D13+E13)/60 -> 6.75
A14: 3 | B14: React: Component, Props, State, Hooks | C14: =SUMIFS('GĐ1 - Fullstack (7 tuần)'!$E$5:$E$95,'GĐ1 - Fullstack (7 tuần)'!$A$5:$A$95,A14,'GĐ1 - Fullstack (7 tuần)'!$C$5:$C$95,"Pre-class") -> 45 | D14: =SUMIFS('GĐ1 - Fullstack (7 tuần)'!$E$5:$E$95,'GĐ1 - Fullstack (7 tuần)'!$A$5:$A$95,A14,'GĐ1 - Fullstack (7 tuần)'!$C$5:$C$95,"Buổi 1") -> 180 | E14: =SUMIFS('GĐ1 - Fullstack (7 tuần)'!$E$5:$E$95,'GĐ1 - Fullstack (7 tuần)'!$A$5:$A$95,A14,'GĐ1 - Fullstack (7 tuần)'!$C$5:$C$95,"Buổi 2*") -> 180 | F14: =(D14+E14)/60 -> 6 | G14: =(C14+D14+E14)/60 -> 6.75
A15: 4 | B15: React: Forms, Context, Routing | C15: =SUMIFS('GĐ1 - Fullstack (7 tuần)'!$E$5:$E$95,'GĐ1 - Fullstack (7 tuần)'!$A$5:$A$95,A15,'GĐ1 - Fullstack (7 tuần)'!$C$5:$C$95,"Pre-class") -> 45 | D15: =SUMIFS('GĐ1 - Fullstack (7 tuần)'!$E$5:$E$95,'GĐ1 - Fullstack (7 tuần)'!$A$5:$A$95,A15,'GĐ1 - Fullstack (7 tuần)'!$C$5:$C$95,"Buổi 1") -> 180 | E15: =SUMIFS('GĐ1 - Fullstack (7 tuần)'!$E$5:$E$95,'GĐ1 - Fullstack (7 tuần)'!$A$5:$A$95,A15,'GĐ1 - Fullstack (7 tuần)'!$C$5:$C$95,"Buổi 2*") -> 180 | F15: =(D15+E15)/60 -> 6 | G15: =(C15+D15+E15)/60 -> 6.75
A16: 5 | B16: Node.js + Express REST API | C16: =SUMIFS('GĐ1 - Fullstack (7 tuần)'!$E$5:$E$95,'GĐ1 - Fullstack (7 tuần)'!$A$5:$A$95,A16,'GĐ1 - Fullstack (7 tuần)'!$C$5:$C$95,"Pre-class") -> 45 | D16: =SUMIFS('GĐ1 - Fullstack (7 tuần)'!$E$5:$E$95,'GĐ1 - Fullstack (7 tuần)'!$A$5:$A$95,A16,'GĐ1 - Fullstack (7 tuần)'!$C$5:$C$95,"Buổi 1") -> 180 | E16: =SUMIFS('GĐ1 - Fullstack (7 tuần)'!$E$5:$E$95,'GĐ1 - Fullstack (7 tuần)'!$A$5:$A$95,A16,'GĐ1 - Fullstack (7 tuần)'!$C$5:$C$95,"Buổi 2*") -> 180 | F16: =(D16+E16)/60 -> 6 | G16: =(C16+D16+E16)/60 -> 6.75
A17: 6 | B17: Database với Sequelize | C17: =SUMIFS('GĐ1 - Fullstack (7 tuần)'!$E$5:$E$95,'GĐ1 - Fullstack (7 tuần)'!$A$5:$A$95,A17,'GĐ1 - Fullstack (7 tuần)'!$C$5:$C$95,"Pre-class") -> 45 | D17: =SUMIFS('GĐ1 - Fullstack (7 tuần)'!$E$5:$E$95,'GĐ1 - Fullstack (7 tuần)'!$A$5:$A$95,A17,'GĐ1 - Fullstack (7 tuần)'!$C$5:$C$95,"Buổi 1") -> 180 | E17: =SUMIFS('GĐ1 - Fullstack (7 tuần)'!$E$5:$E$95,'GĐ1 - Fullstack (7 tuần)'!$A$5:$A$95,A17,'GĐ1 - Fullstack (7 tuần)'!$C$5:$C$95,"Buổi 2*") -> 180 | F17: =(D17+E17)/60 -> 6 | G17: =(C17+D17+E17)/60 -> 6.75
A18: 7 | B18: Tích hợp + Thi cuối Giai đoạn 1 | C18: =SUMIFS('GĐ1 - Fullstack (7 tuần)'!$E$5:$E$95,'GĐ1 - Fullstack (7 tuần)'!$A$5:$A$95,A18,'GĐ1 - Fullstack (7 tuần)'!$C$5:$C$95,"Pre-class") -> 0 | D18: =SUMIFS('GĐ1 - Fullstack (7 tuần)'!$E$5:$E$95,'GĐ1 - Fullstack (7 tuần)'!$A$5:$A$95,A18,'GĐ1 - Fullstack (7 tuần)'!$C$5:$C$95,"Buổi 1") -> 180 | E18: =SUMIFS('GĐ1 - Fullstack (7 tuần)'!$E$5:$E$95,'GĐ1 - Fullstack (7 tuần)'!$A$5:$A$95,A18,'GĐ1 - Fullstack (7 tuần)'!$C$5:$C$95,"Buổi 2*") -> 180 | F18: =(D18+E18)/60 -> 6 | G18: =(C18+D18+E18)/60 -> 6
A19: Tổng GĐ1 | C19: =SUM(C12:C18) -> 270 | D19: =SUM(D12:D18) -> 1260 | E19: =SUM(E12:E18) -> 1260 | F19: =SUM(F12:F18) -> 42 | G19: =SUM(G12:G18) -> 46.5
A21: TỔNG HỢP TOÀN KHÓA
A22: Giai đoạn | B22: Số tuần | C22: Giờ có GV/Mentor | D22: Giờ tự học | E22: Tổng giờ | F22: Số tháng (≈)
A23: GĐ1 · Fullstack nền tảng | B23: =COUNT(A12:A18) -> 7 | C23: =F19 -> 42 | D23: =C19/60 -> 4.5 | E23: =C23+D23 -> 46.5 | F23: =B23/(52/12) -> 1.6153846
A24: GĐ2 · AI-Driven SDLC (M1–M4) | B24: =COUNT('GĐ2 - AI SDLC (12 tuần)'!A5:A16) -> 12 | C24: =B24*$B$5*$B$7 -> 72 | D24: =B24*$B$5*($B$6-$B$7) -> 36 | E24: =C24+D24 -> 108 | F24: =B24/(52/12) -> 2.7692308
A25: GĐ3 · Capstone & OJT | B25: =COUNT('GĐ3 - Capstone & OJT (7 tuần)'!A5:A11) -> 7 | C25: =B25*$B$8 -> 63 | D25: =0 -> 0 | E25: =C25+D25 -> 63 | F25: =B25/(52/12) -> 1.6153846
A26: Tổng | B26: =SUM(B23:B25) -> 26 | C26: =SUM(C23:C25) -> 177 | D26: =SUM(D23:D25) -> 40.5 | E26: =SUM(E23:E25) -> 217.5 | F26: =SUM(F23:F25) -> 6
A28: SO SÁNH VỚI LỘ TRÌNH CŨ
A29: Phần | B29: Lộ trình cũ (tuần) | C29: Đề xuất (tuần) | D29: Chênh lệch (tuần) | E29: % giảm
A30: Fullstack nền tảng | B30: =COUNTIF('So sánh cũ - mới'!$B$5:$B$41,"GĐ1") -> 10 | C30: =B23 -> 7 | D30: =C30-B30 -> -3 | E30: =IF(B30=0,0,-D30/B30) -> 0.3
A31: AI-SDLC Module 1–4 | B31: =COUNTIF('So sánh cũ - mới'!$B$5:$B$41,"GĐ2 M1")+COUNTIF('So sánh cũ - mới'!$B$5:$B$41,"GĐ2 M2")+COUNTIF('So sánh cũ - mới'!$B$5:$B$41,"GĐ2 M3")+COUNTIF('So sánh cũ - mới'!$B$5:$B$41,"GĐ2 M4") -> 18 | C31: =B24 -> 12 | D31: =C31-B31 -> -6 | E31: =IF(B31=0,0,-D31/B31) -> 0.33333333
A32: Capstone & OJT | B32: =COUNTIF('So sánh cũ - mới'!$B$5:$B$41,"GĐ2 M5")+COUNTIF('So sánh cũ - mới'!$B$5:$B$41,"GĐ3 OJT") -> 9 | C32: =B25 -> 7 | D32: =C32-B32 -> -2 | E32: =IF(B32=0,0,-D32/B32) -> 0.22222222
A33: Tổng | B33: =SUM(B30:B32) -> 37 | C33: =SUM(C30:C32) -> 26 | D33: =SUM(D30:D32) -> -11 | E33: =IF(B33=0,0,-D33/B33) -> 0.2972973
A35: Ghi chú: Số tháng tính theo 52/12 ≈ 4,33 tuần/tháng. GĐ1 cũ ghi 60 giờ nhưng chỉ 39,5 giờ có kế hoạch chi tiết.

Sheet GĐ1 - Fullstack (7 tuần)
A1: GIAI ĐOẠN 1: FULLSTACK WEB DEVELOPMENT (7 TUẦN)
A2: Flipped classroom: tự học trước ~45 phút + Buổi 1 (3 giờ) + Buổi 2 (3 giờ) mỗi tuần
A4: Tuần | B4: Chủ đề | C4: Buổi | D4: Hoạt động / Nội dung | E4: Phút | F4: Ghi chú
A5: 1 | B5: Git + HTML/CSS Responsive | C5: Mục tiêu | D5: Thiết lập môi trường, nắm Git workflow và dựng UI tĩnh Blog responsive | F5: Gộp từ: GĐ1 cũ T1 + T2
A6: 1 | B6: Git + HTML/CSS Responsive | C6: Pre-class | D6: Video: Cài đặt môi trường (Node.js, VS Code, Git) & Git cơ bản | E6: 15 | F6: Cài đặt chuyển hẳn sang e-learning
A7: 1 | B7: Git + HTML/CSS Responsive | C7: Pre-class | D7: Video: HTML5 semantic, Flexbox & Grid | E7: 20 | F7: header, nav, main, article; layout
A8: 1 | B8: Git + HTML/CSS Responsive | C8: Pre-class | D8: Reading: Git cheat sheet + BEM naming | E8: 5 | F8: Các lệnh thường dùng, Block-Element-Modifier
A9: 1 | B9: Git + HTML/CSS Responsive | C9: Pre-class | D9: Quiz: Git, HTML/CSS | E9: 5 | F9: 8 câu trắc nghiệm
A10: 1 | B10: Git + HTML/CSS Responsive | C10: Buổi 1 | D10: Q&A từ pre-class | E10: 15 | F10: Giải đáp thắc mắc
A11: 1 | B11: Git + HTML/CSS Responsive | C11: Buổi 1 | D11: Tổng hợp kiến thức: Git workflow & layout | E11: 30 | F11: Branch, PR, conventional commit; Flexbox vs Grid
A12: 1 | B12: Git + HTML/CSS Responsive | C12: Buổi 1 | D12: Case study | E12: 45 | F12: "Workspace lộn xộn → Git conflict hàng loạt"
A13: 1 | B13: Git + HTML/CSS Responsive | C13: Buổi 1 | D13: Workshop + Lab 1.1 | E13: 90 | F13: Tạo repo chuẩn, branch, commit, Pull Request
A14: 1 | B14: Git + HTML/CSS Responsive | C14: Buổi 2 | D14: Briefing bài lab | E14: 15 | F14: Yêu cầu Lab 1.2
A15: 1 | B15: Git + HTML/CSS Responsive | C15: Buổi 2 | D15: Lab 1.2 có hướng dẫn | E15: 120 | F15: Blog UI: Header, Sidebar, Main, Footer + responsive
A16: 1 | B16: Git + HTML/CSS Responsive | C16: Buổi 2 | D16: Review, chấm nhanh, preview tuần sau | E16: 45 | F16: Nhận xét, preview JS ES6+
A17: 1 | B17: Git + HTML/CSS Responsive | C17: Đầu ra | D17: ✓ Repo GitHub, cấu trúc chuẩn (source/, docs/), .gitignore đúng ✓ ≥3 commit conventional, 1 branch feature merge qua Pull Request ✓ Blog UI: header, sidebar, post list, post detail, footer ✓ Responsive 320px / 768px / 1024px, đặt tên class theo BEM
A18: 2 | B18: JavaScript ES6+ & Async/Fetch API | C18: Mục tiêu | D18: Nắm JavaScript hiện đại và kết nối UI với API qua service layer | F18: Gộp từ: GĐ1 cũ T3 + T4 (bỏ phần fetch bị lặp)
A19: 2 | B19: JavaScript ES6+ & Async/Fetch API | C19: Pre-class | D19: Video: ES6+ (let/const, arrow, destructuring, spread, modules) | E19: 15
A20: 2 | B20: JavaScript ES6+ & Async/Fetch API | C20: Pre-class | D20: Video: Promise, async/await, REST & Fetch API | E20: 20 | F20: Methods, status codes, xử lý lỗi
A21: 2 | B21: JavaScript ES6+ & Async/Fetch API | C21: Pre-class | D21: Reading: Service layer pattern | E21: 5 | F21: Tách API logic khỏi giao diện
A22: 2 | B22: JavaScript ES6+ & Async/Fetch API | C22: Pre-class | D22: Quiz: ES6 & API | E22: 5 | F22: 8 câu
A23: 2 | B23: JavaScript ES6+ & Async/Fetch API | C23: Buổi 1 | D23: Q&A từ pre-class | E23: 15
A24: 2 | B24: JavaScript ES6+ & Async/Fetch API | C24: Buổi 1 | D24: Tổng hợp kiến thức: array methods, async, REST | E24: 30
A25: 2 | B25: JavaScript ES6+ & Async/Fetch API | C25: Buổi 1 | D25: Case study | E25: 45 | F25: "API trả 200 nhưng data rỗng": debug case
A26: 2 | B26: JavaScript ES6+ & Async/Fetch API | C26: Buổi 1 | D26: Workshop + Lab 2.1 | E26: 90 | F26: map, filter, reduce, find trên dữ liệu posts
A27: 2 | B27: JavaScript ES6+ & Async/Fetch API | C27: Buổi 2 | D27: Briefing bài lab | E27: 15
A28: 2 | B28: JavaScript ES6+ & Async/Fetch API | C28: Buổi 2 | D28: Lab 2.2 có hướng dẫn | E28: 120 | F28: json-server + api.js, nối Blog UI với API
A29: 2 | B29: JavaScript ES6+ & Async/Fetch API | C29: Buổi 2 | D29: Review, chấm nhanh, preview tuần sau | E29: 45 | F29: Preview React
A30: 2 | B30: JavaScript ES6+ & Async/Fetch API | C30: Đầu ra | D30: ✓ Array methods: map, filter, reduce, find, some, every ✓ async/await với try-catch, ES Modules import/export ✓ json-server chạy với posts.json; service layer api.js ✓ Loading / Error (có nút retry) / Empty state cho PostList, PostDetail, Search
A31: 3 | B31: React: Component, Props, State, Hooks | C31: Mục tiêu | D31: Chuyển Blog sang React, nắm Component, Props, State và useEffect | F31: Gộp từ: GĐ1 cũ T5 + useEffect của T6
A32: 3 | B32: React: Component, Props, State, Hooks | C32: Pre-class | D32: Video: Tạo project React với Vite | E32: 10
A33: 3 | B33: React: Component, Props, State, Hooks | C33: Pre-class | D33: Video: Components & Props | E33: 10 | F33: Functional components
A34: 3 | B34: React: Component, Props, State, Hooks | C34: Pre-class | D34: Video: useState & useEffect | E34: 15 | F34: State, side effects, cleanup
A35: 3 | B35: React: Component, Props, State, Hooks | C35: Pre-class | D35: Reading: Thinking in React | E35: 5 | F35: Chia component, đặt state ở đâu
A36: 3 | B36: React: Component, Props, State, Hooks | C36: Pre-class | D36: Quiz: React basics | E36: 5 | F36: 8 câu
A37: 3 | B37: React: Component, Props, State, Hooks | C37: Buổi 1 | D37: Q&A từ pre-class | E37: 15
A38: 3 | B38: React: Component, Props, State, Hooks | C38: Buổi 1 | D38: Tổng hợp kiến thức: component tree, data flow | E38: 30
A39: 3 | B39: React: Component, Props, State, Hooks | C39: Buổi 1 | D39: Case study | E39: 45 | F39: "Khi nào dùng State, khi nào dùng Props?"
A40: 3 | B40: React: Component, Props, State, Hooks | C40: Buổi 1 | D40: Workshop + Lab 3.1 | E40: 90 | F40: Tách Blog thành Header, PostList, PostCard, PostDetail
A41: 3 | B41: React: Component, Props, State, Hooks | C41: Buổi 2 | D41: Briefing bài lab | E41: 15
...

Sheet GĐ2 - AI SDLC (12 tuần)
A1: GIAI ĐOẠN 2: AI-DRIVEN SOFTWARE DEVELOPMENT LIFE CYCLE (12 TUẦN)
A2: 3 buổi/tuần: Buổi 1 tự học · Buổi 2 Mentor (demo + giao bài) · Buổi 3 Giảng viên (đề tài + review)
A4: Tuần | B4: Module | C4: Chủ đề | D4: Buổi 1: Tự học (3h) | E4: Buổi 2: Mentor (3h) | F4: Buổi 3: Giảng viên (3h) | G4: Đầu ra | H4: Gộp từ lộ trình cũ
A5: 8 | B5: M1 · AI-assisted Programming | C5: AI SDLC toàn cảnh + Workspace & Memory | D5: Toàn cảnh AI SDLC; assisted / agentic / vibe / human-controlled; chi phí & chọn model; hallucination; workspace, external memory (Obsidian), context pollution, memory hygiene | E5: Demo phân tích 1 task có/không AI; demo setup workspace + vault Obsidian; giao bài | F5: So sánh SDLC truyền thống vs agentic; live case AI sai bảo mật; thiết lập workspace kiểm soát trên project nhiễu | G5: task-analysis.md, model-cost-note.md, workspace-setup.md, memory-map.md | H5: GĐ2 cũ T1 + T2
A6: 9 | B6: M1 · AI-assisted Programming | C6: AGENTS.md, Governance, MCP + Thi Phase I | D6: AGENTS.md, prompt/review log; thiết kế & phân rã task; MCP least-privilege, đa agent; hallucination checklist | E6: Demo viết AGENTS.md + giao task cho agent; mock exam & rà evidence | F6: Giao task agent, review output, mini-defense + THI THỰC HÀNH PHASE I | G6: AGENTS.md, prompt-log, review-log, hallucination-checklist | H6: GĐ2 cũ T3
A7: 10 | B7: M2 · Spec-first SE | C7: Requirement, MoSCoW + User Story & AC | D7: FR/NFR/business rule/constraint; MoSCoW; 3C, INVEST, Gherkin, DoR/DoD; PII checklist | E7: Demo chuẩn hóa requirement + viết story/AC bằng AI; giao bài | F7: Phân loại, ưu tiên, mask PII trên case thật; viết story + AC; review clinic | G7: requirements.md, moscow-priority.md, user-stories.md (AC Gherkin), pii-checklist | H7: GĐ2 cũ T4 + T5
A8: 11 | B8: M2 · Spec-first SE | C8: Wireframe + Database Contract & ERD | D8: Lo-fi wireframe, screen list; entity, PK/FK, quan hệ, constraint, migration/seed | E8: Demo dựng wireframe bằng AI + dựng ERD; giao bài | F8: PO duyệt wireframe (sign-off); thiết kế ERD ≥5 bảng; review clinic lỗi DB | G8: wireframe, screen-list, erd, database-design.md | H8: GĐ2 cũ T5 + T6
A9: 12 | B9: M2 · Spec-first SE | C9: API contract, Traceability, Plan, ADR + Thi Phase II | D9: REST spec, error model, traceability matrix; ADR; lập plan từ spec (backlog + slice) | E9: Demo API spec + ADR + implementation plan; mock spec review | F9: Thiết kế API + traceability; chốt plan + THI THỰC HÀNH PHASE II | G9: api-spec (OpenAPI), error-model, traceability-matrix, ADR, implementation-plan | H9: GĐ2 cũ T7 (thêm ADR)
A10: 13 | B10: M3 · Agentic Fullstack | C10: TDD + Git workflow + Task contract | D10: Test-first, TDD, unit/integration/E2E; mutation testing cơ bản; branch-per-task, PR, revert; task contract | E10: Demo test skeleton + PR/revert + task contract; giao bài | F10: AC → test; dựng Git workflow; revert 1 thay đổi agent sai; chạy mutation test trên 1 module; TDD clinic | G10: test-cases, git-workflow.md, task-contract.md, mutation-report (mini) | H10: GĐ2 cũ T8 + T9
A11: 14 | B11: M3 · Agentic Fullstack | C11: Backend qua agent + DB + Auth | D11: Controller-Service-Repository, DTO, validation; DB integration; JWT auth, permission; integration test | E11: Demo giao task backend cho agent + viết integration test | F11: Triển khai backend feature + auth qua agent; review & refactor; clinic | G11: Backend feature + auth, integration test pass, review-log | H11: GĐ2 cũ T9 + T10, GĐ1 cũ T9
A12: 15 | B12: M3 · Agentic Fullstack | C12: Frontend + Tích hợp fullstack + E2E | D12: Component, service layer, states, route guard; FE–BE integration, CORS/mismatch, E2E | E12: Demo FE slice gọi API thật + E2E flow | F12: Dựng vertical slice fullstack + E2E verification; clinic | G12: FE vertical slice, E2E test, evidence | H12: GĐ2 cũ T11 + T12
A13: 16 | B13: M3 · Agentic Fullstack | C13: Diff review, Refactor + Thi Phase III | D13: Đọc diff, code smell, refactor có kiểm soát; ôn vertical slice | E13: Demo review diff + refactor; mock diff review | F13: Review diff của agent + refactor; mini demo + THI THỰC HÀNH PHASE III | G13: diff-review-log, refactor note | H13: GĐ2 cũ T13
A14: 17 | B14: M4 · Security, DevOps, Cloud | C14: Debug, Self-healing + Security & Legal/IP | D14: Stack trace, log, network; phân loại lỗi; self-healing loop, stop condition; SQLi/XSS/BAC/secret, OWASP Top 10; license/IP/đạo đức code AI | E14: Demo debug live + bugfix có stop condition; demo phát hiện lỗ hổng + license check | F14: Tái hiện + vá bug trong scope; rà bảo mật theo OWASP + rủi ro pháp lý; security clinic | G14: bug-tracker, RCA, security-review (OWASP), ai-usage-policy | H14: GĐ2 cũ T14 + T15
A15: 18 | B15: M4 · Security, DevOps, Cloud | C15: Docker, CI, AI review gate + Deploy cloud | D15: Dockerfile, Compose, env, CI; agent tự review diff/PR làm cổng CI; PaaS deploy, secret, HTTPS | E15: Demo compose + CI + bước AI review + deploy | F15: Đóng gói Docker + CI chạy thật; deploy Live URL + smoke test + rollback | G15: Dockerfile, compose, CI pipeline xanh, ai-review-gate-note, deployment-notes, Live URL | H15: GĐ2 cũ T16 + T17
A16: 19 | B16: M4 · Security, DevOps, Cloud | C16: Observability, Maintenance + Thi Phase IV | D16: Logging, error tracking, health check; maintenance: incident, versioning, regression, changelog; ôn tập | E16: Demo logging/health + release checklist; mock exam | F16: Maintenance drill (incident → regression → changelog) + THI THỰC HÀNH PHASE IV: debug + security + Docker/CI + release + 1 change request | G16: observability note, changelog, release checklist | H16: GĐ2 cũ T17 + T18 (bỏ tuần thi riêng)

Sheet GĐ3 - Capstone & OJT (7 tuần)
A1: GIAI ĐOẠN 3: CAPSTONE PROJECT & OJT TRÊN HỆ THỐNG IOC (7 TUẦN)
A2: Làm việc nhóm theo Scrum, mentor đồng hành; Capstone được tính là thời gian OJT
A4: Tuần | B4: Sprint / Gate | C4: Nội dung | D4: Đầu ra | E4: Gộp từ lộ trình cũ
A5: 20 | B5: Kickoff · Gate M0–M1 | C5: Proposal, scope, AI usage policy, team agreement; branching/PR nhóm; chốt spec baseline | D5: Proposal, team agreement, spec baseline + traceability | E5: M5 cũ T19
A6: 21 | B6: Sprint 1 · Backend · Gate M2 | C6: Triển khai backend + integration test qua agent; daily stand-up trên IOC | D6: Backend chạy được, integration test pass | E6: M5 cũ T20
A7: 22 | B7: Sprint 2 · Frontend · Gate M3 | C7: Frontend + fullstack flow + E2E; sprint review với mentor | D7: Fullstack flow + E2E evidence | E7: M5 cũ T21
A8: 23 | B8: Sprint 3 · Hardening · Gate M4–M6 | C8: Diff review/refactor, security, Docker/CI, deploy release v1.0 | D8: Live URL, CI xanh, security report, release v1.0 | E8: M5 cũ T22
A9: 24 | B9: Brownfield 1 | C9: Nhận codebase của nhóm khác; vẽ sơ đồ hệ thống legacy; phân tích change request; viết test bảo vệ hành vi hiện tại | D9: Sơ đồ legacy, phân tích change request, characterization tests | E9: OJT cũ
A10: 25 | B10: Brownfield 2 | C10: Thực hiện change request + sửa bug; regression test; changelog; release v1.1 | D10: Release v1.1, regression report, changelog | E10: OJT cũ
A11: 26 | B11: Defense · Gate M7 | C11: README tiếng Anh, demo, slide; bảo vệ trước hội đồng; đánh giá OJT | D11: Capstone Defense, bản đánh giá năng lực, chứng nhận | E11: M5 cũ T23 + OJT cũ

Sheet So sánh cũ - mới
A1: LỘ TRÌNH CŨ (37 TUẦN) VÀ VỊ TRÍ TRONG LỘ TRÌNH MỚI
A2: Mỗi tuần cũ được gộp, giữ nguyên hoặc chuyển sang tuần nào trong bản 26 tuần
A4: STT | B4: Phần (cũ) | C4: Nội dung tuần cũ | D4: Trong lộ trình mới
A5: 1 | B5: GĐ1 | C5: Workspace setup & Git | D5: Gộp vào tuần mới 1
A6: 2 | B6: GĐ1 | C6: HTML, CSS & Responsive Layout | D6: Gộp vào tuần mới 1
A7: 3 | B7: GĐ1 | C7: JavaScript ES6+ Fundamentals | D7: Gộp vào tuần mới 2
A8: 4 | B8: GĐ1 | C8: API Integration & Fetch | D8: Gộp vào tuần mới 2
A9: 5 | B9: GĐ1 | C9: React Fundamentals | D9: Tuần mới 3
A10: 6 | B10: GĐ1 | C10: React Hooks & Forms | D10: Tuần mới 3–4
A11: 7 | B11: GĐ1 | C11: Node.js & Express API | D11: Tuần mới 5
A12: 8 | B12: GĐ1 | C12: Database with Sequelize | D12: Tuần mới 6
A13: 9 | B13: GĐ1 | C13: Authentication & Security | D13: Chuyển sang tuần mới 14
A14: 10 | B14: GĐ1 | C14: Integration & Final Exam | D14: Tuần mới 7
A15: 11 | B15: GĐ2 M1 | C15: AI-assisted & Agentic SDLC | D15: Gộp vào tuần mới 8
A16: 12 | B16: GĐ2 M1 | C16: Workspace & Agent Memory | D16: Gộp vào tuần mới 8
... A41: 37 | B41: GĐ3 OJT | C41: OJT tuần 4 | D41: Pha Brownfield, tuần mới 24–25
